Workbook

Sheet Model Guide
B2: AIRBUS SE - COMPARABLE COMPANIES ANALYSIS (TRADING COMPS)
B3: LTM/TTM basis, native reporting currency per company - see Sources below for exact data dates
B6: COLOR LEGEND
B7: Blue text | C7: Hardcoded input, sourced from the company's own LTM financials as reported by S&P Global Market Intelligence.
B8: Black text | C8: Formula calculated from other cells on the same sheet (Market Cap, EV, multiples, Mean/Median/Min/Max).
B9: Green text | C9: Link pulling a value from a different sheet in this workbook.
B10: Yellow fill | C10: Key output.
B11: Orange fill | C11: Airbus (the target) - shown alongside the comp set for reference, but excluded from the Mean/Median/Min/Max statistics.
B13: WHY MULTIPLES AREN'T CURRENCY-CONVERTED
C14: EV/Revenue, EV/EBITDA, EV/EBIT and P/E are unitless ratios - a USD company's EV/EBITDA is directly comparable to a EUR or GBP company's, since both numerator and denominator sit in the same currency for each company individually. Converting everyone to one currency would add FX-timing noise for no analytical benefit. Each comp's raw dollar/euro/pound figures are shown in its own reporting currency (clearly labeled); the resulting multiples are applied directly to Airbus's own EUR financials on the Implied Valuation tab, so the output is native EUR throughout - no FX conversion needed anywhere in the chain.
B22: TAB-BY-TAB WALKTHROUGH
B24: 1. Trading Comps | C24: Input (LTM financials per comp), Calculations (Market Cap, EV, multiples), and Output (Mean/Median/Min/Max across the 6 comps) sections, clearly separated; extended with Operating Metrics (margins, ROE) and Forward (NTM) Multiples.
B25: 2. Implied Valuation | C25: Applies the comp set's median (and min/max) multiples to Airbus's own LTM Revenue, EBITDA, EBIT and EPS to derive implied EV, Equity Value and share price under each method, plus the football field chart; also includes Football Field chart, Sensitivity table (multiple flex), and Key Takeaways.
B28: SOURCES (all via S&P Global Market Intelligence, as republished by stockanalysis.com)
B29: - | C29: Airbus SE (EPA:AIR): data as of Jun 5, 2026 close.
B30: - | C30: Boeing (NYSE:BA): data as of Aug 5, 2026 (real-time)/Jul 28, 2026 (financials).
B31: - | C31: Safran SA (EPA:SAF): data as of Jun 23, 2026 close.
B32: - | C32: RTX Corporation (NYSE:RTX): data as of Aug 5, 2026 (real-time).
B33: - | C33: GE Aerospace (NYSE:GE): data as of Aug 5, 2026 (real-time).
B34: - | C34: Rolls-Royce Holdings plc (LON:RR): data as of Jun 5, 2026 close. Share price quoted in GBX (pence) on the source page; converted to GBP (divide by 100) here to match GBP-denominated financials and EPS.
B35: - | C35: Thales S.A. (EPA:HO): data as of Jun 19-20, 2026 close.
B37: NOTE
C38: Comp data was pulled on different dates across a roughly 2-month window (Jun-Aug 2026) since each reflects that company's own most recent trading day at the time of research - normal practice for a comp set built over a single research session, but worth refreshing to a single as-of date before using this in a live deal context.

Sheet Trading Comps
A1: AIRBUS SE - COMPARABLE COMPANIES ANALYSIS
A3: INPUT - COMPARABLE COMPANY DATA (LTM / TTM, native reporting currency)
A5: Company | B5: Ticker | C5: Ccy | D5: Share Price | E5: Shares O/S (m) | F5: Net Debt (m) | G5: Revenue LTM (m) | H5: EBITDA LTM (m) | I5: EBIT LTM (m) | J5: Net Income LTM (m) | K5: EPS LTM | L5: Data Date | M5: Prior Yr Revenue (m) | N5: Shareholders' Equity (m) | O5: NTM Revenue (m) | P5: NTM EPS
A6: Boeing | B6: BA | C6: USD | D6: 240.02 | E6: 790.37 | F6: 29070 | G6: 94000 | H6: 6800 | I6: 4600 | J6: 2090 | K6: 2.68 | L6: Aug 5, 2026 | M6: 75330 | N6: 6115 | O6: 97000 | P6: 2.85
A7: Safran | B7: SAF | C7: EUR | D7: 328.2 | E7: 414.61 | F7: -1520 | G7: 31190 | H7: 5910 | I7: 4560 | J7: 7180 | K7: 17.17 | L7: Jun 23, 2026 | M7: 27230 | N7: 12900 | O7: 34930 | P7: 19.5
A8: RTX Corporation | B8: RTX | C8: USD | D8: 221.95 | E8: 1350 | F8: 30550 | G8: 93500 | H8: 14890 | I8: 10490 | J8: 7740 | K8: 5.68 | L8: Aug 5, 2026 | M8: 85200 | N8: 66900 | O8: 94000 | P8: 6.88
A9: GE Aerospace | B9: GE | C9: USD | D9: 381.22 | E9: 1040 | F9: 10290 | G9: 50640 | H9: 10590 | I9: 9360 | J9: 8970 | K9: 8.49 | L9: Aug 5, 2026 | M9: 41610 | N9: 19745 | O9: 59800 | P9: 7.5
A10: Rolls-Royce Holdings | B10: RR. | C10: GBP | D10: 12.6 | E10: 8250 | F10: -1890 | G10: 21210 | H10: 4600 | I10: 4190 | J10: 5840 | K10: 0.69 | L10: Jun 5, 2026 | M10: 18910 | N10: 937 | O10: 24390 | P10: 0.79
A11: Thales | B11: HO | C11: EUR | D11: 232.4 | E11: 205.48 | F11: 1640 | G11: 22140 | H11: 3010 | I11: 2180 | J11: 1670 | K11: 8.13 | L11: Jun 19, 2026 | M11: 19920 | N11: 7915 | O11: 23910 | P11: 8.78
A13: Airbus SE (TARGET) | B13: AIR | C13: EUR | D13: 178.96 | E13: 787.23 | F13: -1210 | G13: 72530 | H13: 7650 | I13: 5380 | J13: 5010 | K13: 6.33 | L13: Jun 5, 2026 | M13: 69940 | N13: 25370 | O13: 75430 | P13: 6.71
A16: CALCULATIONS - MARKET CAP, ENTERPRISE VALUE & TRADING MULTIPLES (LTM)
A18: Company | B18: Market Cap (m) | C18: Enterprise Value (m) | D18: EV / Revenue | E18: EV / EBITDA | F18: EV / EBIT | G18: P / E
A19: =A6 -> Boeing | B19: =D6*E6 -> 189704.61 | C19: =B19+F6 -> 218774.61 | D19: =C19/G6 -> 2.3273894 | E19: =C19/H6 -> 32.172736 | F19: =C19/I6 -> 47.559697 | G19: =D6/K6 -> 89.559701
A20: =A7 -> Safran | B20: =D7*E7 -> 136075 | C20: =B20+F7 -> 134555 | D20: =C20/G7 -> 4.314043 | E20: =C20/H7 -> 22.767344 | F20: =C20/I7 -> 29.507676 | G20: =D7/K7 -> 19.114735
A21: =A8 -> RTX Corporation | B21: =D8*E8 -> 299632.5 | C21: =B21+F8 -> 330182.5 | D21: =C21/G8 -> 3.5313636 | E21: =C21/H8 -> 22.174782 | F21: =C21/I8 -> 31.475929 | G21: =D8/K8 -> 39.075704
A22: =A9 -> GE Aerospace | B22: =D9*E9 -> 396468.8 | C22: =B22+F9 -> 406758.8 | D22: =C22/G9 -> 8.0323618 | E22: =C22/H9 -> 38.409707 | F22: =C22/I9 -> 43.457137 | G22: =D9/K9 -> 44.902238
A23: =A10 -> Rolls-Royce Holdings | B23: =D10*E10 -> 103950 | C23: =B23+F10 -> 102060 | D23: =C23/G10 -> 4.8118812 | E23: =C23/H10 -> 22.186957 | F23: =C23/I10 -> 24.357995 | G23: =D10/K10 -> 18.26087
A24: =A11 -> Thales | B24: =D11*E11 -> 47753.552 | C24: =B24+F11 -> 49393.552 | D24: =C24/G11 -> 2.2309644 | E24: =C24/H11 -> 16.409818 | F24: =C24/I11 -> 22.657593 | G24: =D11/K11 -> 28.585486
A26: Airbus SE (TARGET) | B26: =D13*E13 -> 140882.68 | C26: =B26+F13 -> 139672.68 | D26: =C26/G13 -> 1.9257229 | E26: =C26/H13 -> 18.257867 | F26: =C26/I13 -> 25.961465 | G26: =D13/K13 -> 28.271722
A29: OUTPUT - SUMMARY STATISTICS (6 comparable companies; Airbus excluded)
A31: Statistic | B31: EV / Revenue | C31: EV / EBITDA | D31: EV / EBIT | E31: P / E
A32: Mean | B32: =AVERAGE(D19:D24) -> 4.2080006 | C32: =AVERAGE(E19:E24) -> 25.686891 | D32: =AVERAGE(F19:F24) -> 33.169338 | E32: =AVERAGE(G19:G24) -> 39.916456
A33: Median | B33: =MEDIAN(D19:D24) -> 3.9227033 | C33: =MEDIAN(E19:E24) -> 22.47715 | D33: =MEDIAN(F19:F24) -> 30.491803 | E33: =MEDIAN(G19:G24) -> 33.830595
A34: Minimum | B34: =MIN(D19:D24) -> 2.2309644 | C34: =MIN(E19:E24) -> 16.409818 | D34: =MIN(F19:F24) -> 22.657593 | E34: =MIN(G19:G24) -> 18.26087
A35: Maximum | B35: =MAX(D19:D24) -> 8.0323618 | C35: =MAX(E19:E24) -> 38.409707 | D35: =MAX(F19:F24) -> 47.559697 | E35: =MAX(G19:G24) -> 89.559701
A38: OPERATING METRICS
A40: Company | B40: Revenue Growth % | C40: EBITDA Margin % | D40: EBIT Margin % | E40: Net Margin % | F40: ROE %
A41: =A6 -> Boeing | B41: =(G6-M6)/M6 -> 0.24784282 | C41: =H6/G6 -> 0.072340426 | D41: =I6/G6 -> 0.04893617 | E41: =J6/G6 -> 0.022234043 | F41: =J6/N6 -> 0.3417825
A42: =A7 -> Safran | B42: =(G7-M7)/M7 -> 0.14542784 | C42: =H7/G7 -> 0.18948381 | D42: =I7/G7 -> 0.14620071 | E42: =J7/G7 -> 0.23020199 | F42: =J7/N7 -> 0.55658915
A43: =A8 -> RTX Corporation | B43: =(G8-M8)/M8 -> 0.09741784 | C43: =H8/G8 -> 0.15925134 | D43: =I8/G8 -> 0.11219251 | E43: =J8/G8 -> 0.082780749 | F43: =J8/N8 -> 0.11569507
A44: =A9 -> GE Aerospace | B44: =(G9-M9)/M9 -> 0.21701514 | C44: =H9/G9 -> 0.20912322 | D44: =I9/G9 -> 0.18483412 | E44: =J9/G9 -> 0.1771327 | F44: =J9/N9 -> 0.45429223
A45: =A10 -> Rolls-Royce Holdings | B45: =(G10-M10)/M10 -> 0.12162877 | C45: =H10/G10 -> 0.21687883 | D45: =I10/G10 -> 0.19754833 | E45: =J10/G10 -> 0.27534182 | F45: =J10/N10 -> 6.2326574
A46: =A11 -> Thales | B46: =(G11-M11)/M11 -> 0.11144578 | C46: =H11/G11 -> 0.13595303 | D46: =I11/G11 -> 0.098464318 | E46: =J11/G11 -> 0.075429088 | F46: =J11/N11 -> 0.21099179
A48: Airbus SE (TARGET) | B48: =(G13-M13)/M13 -> 0.037031741 | C48: =H13/G13 -> 0.1054736 | D48: =I13/G13 -> 0.074176203 | E48: =J13/G13 -> 0.069074866 | F48: =J13/N13 -> 0.19747734
A50: Statistic | B50: Revenue Growth % | C50: EBITDA Margin % | D50: EBIT Margin % | E50: Net Margin % | F50: ROE %
A51: Mean | B51: =AVERAGE(B41:B46) -> 0.15679637 | C51: =AVERAGE(C41:C46) -> 0.16383844 | D51: =AVERAGE(D41:D46) -> 0.13136269 | E51: =AVERAGE(E41:E46) -> 0.1438534 | F51: =AVERAGE(F41:F46) -> 1.318668
A52: Median | B52: =MEDIAN(B41:B46) -> 0.1335283 | C52: =MEDIAN(C41:C46) -> 0.17436757 | D52: =MEDIAN(D41:D46) -> 0.12919661 | E52: =MEDIAN(E41:E46) -> 0.12995673 | F52: =MEDIAN(F41:F46) -> 0.39803736
A53: Minimum | B53: =MIN(B41:B46) -> 0.09741784 | C53: =MIN(C41:C46) -> 0.072340426 | D53: =MIN(D41:D46) -> 0.04893617 | E53: =MIN(E41:E46) -> 0.022234043 | F53: =MIN(F41:F46) -> 0.11569507
A54: Maximum | B54: =MAX(B41:B46) -> 0.24784282 | C54: =MAX(C41:C46) -> 0.21687883 | D54: =MAX(D41:D46) -> 0.19754833 | E54: =MAX(E41:E46) -> 0.27534182 | F54: =MAX(F41:F46) -> 6.2326574
A56: FORWARD VALUATION MULTIPLES (NTM) - clearly distinct from LTM multiples above
...

Sheet Implied Valuation
A1: AIRBUS SE - IMPLIED VALUATION FROM TRADING COMPS
A3: AIRBUS SE - LTM FINANCIALS (linked from Trading Comps)
A4: Share Price (EUR) | B4: ='Trading Comps'!D13 -> 178.96
A5: Shares Outstanding (m) | B5: ='Trading Comps'!E13 -> 787.23
A6: Net Debt (EURm) | B6: ='Trading Comps'!F13 -> -1210
A7: Revenue LTM (EURm) | B7: ='Trading Comps'!G13 -> 72530
A8: EBITDA LTM (EURm) | B8: ='Trading Comps'!H13 -> 7650
A9: EBIT LTM (EURm) | B9: ='Trading Comps'!I13 -> 5380
A10: Net Income LTM (EURm) | B10: ='Trading Comps'!J13 -> 5010
A11: EPS LTM (EUR) | B11: ='Trading Comps'!K13 -> 6.33
A13: IMPLIED VALUATION BY METHODOLOGY (median comp multiple applied to Airbus)
A15: Methodology | B15: Median Multiple | C15: Airbus Metric (EURm) | D15: Implied EV (EURm) | E15: Implied Equity Value (EURm) | F15: Implied Share Price (EUR)
A16: EV / Revenue | B16: ='Trading Comps'!B33 -> 3.9227033 | C16: =$B$7 -> 72530 | D16: =B16*C16 -> 284513.67 | E16: =D16-$B$6 -> 285723.67 | F16: =E16/$B$5 -> 362.94815
A17: EV / EBITDA | B17: ='Trading Comps'!C33 -> 22.47715 | C17: =$B$8 -> 7650 | D17: =B17*C17 -> 171950.2 | E17: =D17-$B$6 -> 173160.2 | F17: =E17/$B$5 -> 219.96138
A18: EV / EBIT | B18: ='Trading Comps'!D33 -> 30.491803 | C18: =$B$9 -> 5380 | D18: =B18*C18 -> 164045.9 | E18: =D18-$B$6 -> 165255.9 | F18: =E18/$B$5 -> 209.92073
A19: P / E | B19: ='Trading Comps'!E33 -> 33.830595 | C19: =$B$11 -> 6.33 | D19: =E19+$B$6 -> 167373.47 | E19: =F19*$B$5 -> 168583.47 | F19: =B19*C19 -> 214.14767
A20: Note: EV/Revenue and P/E ranges are wide because the comp set spans Boeing (margin-impaired, EV/EBITDA 32x on depressed EBITDA) to GE Aerospace (premium-rated, EV/EBITDA 38x on strong margins) - EV/EBITDA and EV/EBIT are the more defensible read for this comp set; treat EV/Revenue as a sanity check only.
A22: FOOTBALL FIELD - IMPLIED SHARE PRICE RANGE (EUR)
A24: Methodology | B24: Low (Min multiple) | C24: Median | D24: High (Max multiple) | E24: Bar Base (=Low) | F24: Bar Range (High-Low) | G24: Current Price (ref)
A25: EV / Revenue | B25: =(('Trading Comps'!$B$34*$B$7)-$B$6)/$B$5 -> 207.08287 | C25: =(('Trading Comps'!$B$33*$B$7)-$B$6)/$B$5 -> 362.94815 | D25: =(('Trading Comps'!$B$35*$B$7)-$B$6)/$B$5 -> 741.58403 | E25: =MIN(B25:D25) -> 207.08287 | F25: =MAX(B25:D25)-E25 -> 534.50116 | G25: =$B$4 -> 178.96
A26: EV / EBITDA | B26: =(('Trading Comps'!$C$34*$B$8)-$B$6)/$B$5 -> 161.00137 | C26: =(('Trading Comps'!$C$33*$B$8)-$B$6)/$B$5 -> 219.96138 | D26: =(('Trading Comps'!$C$35*$B$8)-$B$6)/$B$5 -> 374.78788 | E26: =MIN(B26:D26) -> 161.00137 | F26: =MAX(B26:D26)-E26 -> 213.78651 | G26: =$B$4 -> 178.96
A27: EV / EBIT | B27: =(('Trading Comps'!$D$34*$B$9)-$B$6)/$B$5 -> 156.38104 | C27: =(('Trading Comps'!$D$33*$B$9)-$B$6)/$B$5 -> 209.92073 | D27: =(('Trading Comps'!$D$35*$B$9)-$B$6)/$B$5 -> 326.56425 | E27: =MIN(B27:D27) -> 156.38104 | F27: =MAX(B27:D27)-E27 -> 170.1832 | G27: =$B$4 -> 178.96
A28: P / E | B28: ='Trading Comps'!$E$34*$B$11 -> 115.5913 | C28: ='Trading Comps'!$E$33*$B$11 -> 214.14767 | D28: ='Trading Comps'!$E$35*$B$11 -> 566.91291 | E28: =MIN(B28:D28) -> 115.5913 | F28: =MAX(B28:D28)-E28 -> 451.32161 | G28: =$B$4 -> 178.96
A30: Current Share Price (reference line) | B30: =$B$4 -> 178.96
A32: IMPLIED VALUATION SUMMARY (blended: EV/Revenue, EV/EBITDA, EV/EBIT, P/E)
A34: Statistic | B34: Implied EV (EURm) | C34: Implied Equity Value (EURm) | D34: Implied Share Price (EUR)
A35: Mean | B35: =AVERAGE('Trading Comps'!B32*$B$7,'Trading Comps'!C32*$B$8,'Trading Comps'!D32*$B$9,('Trading Comps'!E32*$B$11)+$B$6) -> 169801.18 | C35: =B35-$B$6 -> 171011.18 | D35: =C35/$B$5 -> 217.23153
A36: Median | B36: =AVERAGE('Trading Comps'!B33*$B$7,'Trading Comps'!C33*$B$8,'Trading Comps'!D33*$B$9,('Trading Comps'!E33*$B$11)+$B$6) -> 154878.48 | C36: =B36-$B$6 -> 156088.48 | D36: =C36/$B$5 -> 198.27557
A37: Minimum | B37: =AVERAGE('Trading Comps'!B34*$B$7,'Trading Comps'!C34*$B$8,'Trading Comps'!D34*$B$9,('Trading Comps'!E34*$B$11)+$B$6) -> 102037.6 | C37: =B37-$B$6 -> 103247.6 | D37: =C37/$B$5 -> 131.15303
A38: Maximum | B38: =AVERAGE('Trading Comps'!B35*$B$7,'Trading Comps'!C35*$B$8,'Trading Comps'!D35*$B$9,('Trading Comps'!E35*$B$11)+$B$6) -> 282912.39 | C38: =B38-$B$6 -> 284122.39 | D38: =C38/$B$5 -> 360.91407
A40: Current Share Price (reference) | D40: =$B$4 -> 178.96
A62: SENSITIVITY ANALYSIS - IMPLIED SHARE PRICE vs. MULTIPLE FLEX (EUR)
A64: Multiple Flex | B64: EV/Revenue | C64: EV/EBITDA | D64: EV/EBIT | E64: P/E
A65: -0.2 | B65: =(('Trading Comps'!$B$33*(1+$A65)*$B$7)-$B$6)/$B$5 -> 290.66593 | C65: =(('Trading Comps'!$C$33*(1+$A65)*$B$8)-$B$6)/$B$5 -> 176.27651 | D65: =(('Trading Comps'!$D$33*(1+$A65)*$B$9)-$B$6)/$B$5 -> 168.24399 | E65: =('Trading Comps'!$E$33*(1+$A65))*$B$11 -> 171.31813
A66: -0.1 | B66: =(('Trading Comps'!$B$33*(1+$A66)*$B$7)-$B$6)/$B$5 -> 326.80704 | C66: =(('Trading Comps'!$C$33*(1+$A66)*$B$8)-$B$6)/$B$5 -> 198.11895 | D66: =(('Trading Comps'!$D$33*(1+$A66)*$B$9)-$B$6)/$B$5 -> 189.08236 | E66: =('Trading Comps'!$E$33*(1+$A66))*$B$11 -> 192.7329
A67: 0 | B67: =(('Trading Comps'!$B$33*(1+$A67)*$B$7)-$B$6)/$B$5 -> 362.94815 | C67: =(('Trading Comps'!$C$33*(1+$A67)*$B$8)-$B$6)/$B$5 -> 219.96138 | D67: =(('Trading Comps'!$D$33*(1+$A67)*$B$9)-$B$6)/$B$5 -> 209.92073 | E67: =('Trading Comps'!$E$33*(1+$A67))*$B$11 -> 214.14767
A68: 0.1 | B68: =(('Trading Comps'!$B$33*(1+$A68)*$B$7)-$B$6)/$B$5 -> 399.08926 | C68: =(('Trading Comps'!$C$33*(1+$A68)*$B$8)-$B$6)/$B$5 -> 241.80382 | D68: =(('Trading Comps'!$D$33*(1+$A68)*$B$9)-$B$6)/$B$5 -> 230.7591 | E68: =('Trading Comps'!$E$33*(1+$A68))*$B$11 -> 235.56243
A69: 0.2 | B69: =(('Trading Comps'!$B$33*(1+$A69)*$B$7)-$B$6)/$B$5 -> 435.23037 | C69: =(('Trading Comps'!$C$33*(1+$A69)*$B$8)-$B$6)/$B$5 -> 263.64625 | D69: =(('Trading Comps'!$D$33*(1+$A69)*$B$9)-$B$6)/$B$5 -> 251.59747 | E69: =('Trading Comps'!$E$33*(1+$A69))*$B$11 -> 256.9772
A71: Flex applied to each methodology's median comp multiple (Trading Comps row 33); 0% = base case shown in the Implied Valuation Summary above.
A73: KEY TAKEAWAYS
...
