Workbook

Sheet Model Guide
B2: LVMH - COMPARABLE COMPANIES ANALYSIS (TRADING COMPS)
B3: LTM/TTM basis, native reporting currency per company - see Sources below for exact data dates
B6: COLOR LEGEND
B7: Blue text | C7: Hardcoded input, sourced from the company's own LTM financials as reported by S&P Global Market Intelligence.
B8: Black text | C8: Formula calculated from other cells on the same sheet.
B9: Green text | C9: Link pulling a value from a different sheet in this workbook.
B10: Yellow fill | C10: Key output.
B11: Orange fill | C11: LVMH (the target) - shown alongside the comp set for reference, but excluded from Mean/Median/Min/Max.
B13: COMPANY OVERVIEW - LVMH
C14: LVMH Moet Hennessy - Louis Vuitton SE (EPA:MC) is the world's largest luxury goods group, operating ~75 Maisons across five segments: Wine & Spirits (Moet, Hennessy), Fashion & Leather Goods (Louis Vuitton, Dior, Fendi, Loro Piana), Perfumes & Cosmetics (Parfums Christian Dior, Guerlain), Watches & Jewelry (Tiffany & Co., Bulgari, TAG Heuer) and Selective Retailing (Sephora, DFS). FY2025 revenue of ~EUR 80.8bn makes it roughly 5x the size of its nearest pure-play peer, so the comp set below is built on business-model and margin-structure similarity rather than exact scale.
B16: COMPARABLE SELECTION RATIONALE
B17: Hermes (EPA:RMS) | C17: Ultra-luxury leather goods peer; the closest read-across for LVMH's Fashion & Leather Goods segment (Louis Vuitton, Dior) on brand positioning and pricing power, though smaller and single-segment.
C18: Limitations: single-Maison, no conglomerate discount/diversification effect; far smaller revenue base skews growth and margin comparisons.
C19: Vs. LVMH: superior margins/pricing power but 1/5th the scale and single-segment; still appropriate as the purest read on ultra-luxury leather goods economics within LVMH's largest segment.
B21: Kering (EPA:KER) | C21: Direct multi-brand luxury conglomerate peer (Gucci, Saint Laurent, Bottega Veneta); most comparable house structure to LVMH, currently in a margin-recovery phase which widens its multiples.
C22: Limitations: depressed near-term margins from Gucci turnaround distort multiples upward (denominator effect); not steady-state.
C23: Vs. LVMH: closest structural analog (multi-brand luxury house) though currently margin-impaired; still appropriate as the primary conglomerate-structure comp, with its P/E treated as NM (see Trading Comps).
B25: Richemont (SWX:CFR) | C25: Global luxury conglomerate skewed to Watches & Jewelry (Cartier, Van Cleef & Arpels) - the best available comp for LVMH's Watches & Jewelry segment.
C26: Limitations: Mar fiscal year-end misaligns LTM window vs peers; Watches & Jewelry-heavy mix is not representative of LVMH's Fashion & Leather Goods weight.
C27: Vs. LVMH: comparable diversified-house model but weighted to hard luxury; still appropriate as the only listed large-cap proxy for LVMH's Watches & Jewelry segment.
B29: Prada (HKG:1913) | C29: Fashion & leather goods pure-play (Prada, Miu Miu) post-Versace acquisition; useful for benchmarking brand-portfolio integration economics similar to LVMH's serial M&A model.
C30: Limitations: HKD-listed, thinner trading liquidity than European peers; recent Versace integration muddies underlying organic growth.
C31: Vs. LVMH: smaller and earlier-stage in its brand turnaround, but similar serial-acquisition strategy; still appropriate for benchmarking M&A integration economics.
B33: Moncler (BIT:MONC) | C33: Smaller premium/luxury outerwear house; included for growth-profile and margin comparability at the higher end of 'accessible luxury'.
C34: Limitations: much smaller scale, single-category (outerwear) exposure limits read-across to LVMH's diversified portfolio.
C35: Vs. LVMH: narrower category exposure and smaller scale, but comparable premium positioning and growth algorithm; still appropriate as a growth/margin bookend.
B37: Brunello Cucinelli (BIT:BC) | C37: Ultra-premium ready-to-wear peer with a distinctive high-multiple, low-leverage profile; included as a growth/quality bookend to the comp set.
C38: Limitations: smallest, family-controlled, low free float; premium multiple reflects scarcity/quality more than comparable business mix.
C39: Vs. LVMH: far smaller and lower free float, but shares ultra-premium brand equity and pricing discipline; still appropriate as a quality/scarcity-premium bookend.
B41: COMPANIES CONSIDERED & EXCLUDED
B42: L'Oreal (EPA:OR) | C42: Excluded: primarily mass/prestige beauty and cosmetics, not luxury fashion/leather goods/jewelry; different channel mix (mass retail, drugstore) and margin structure make it a poor read-across despite some Perfumes & Cosmetics overlap.
B43: Burberry (LSE:BRBY) | C43: Excluded: smaller, single-brand, and mid-2020s brand-repositioning/turnaround distorts LTM margins and multiples to an outlier degree.
B44: Ferrari (BIT:RACE) | C44: Excluded: ultra-luxury by price point but automotive, not soft-luxury/fashion; different capex intensity, margin drivers and multiple basis.
B45: Estee Lauder (NYSE:EL) | C45: Excluded: prestige beauty, not fashion/leather goods; distribution model (department stores, travel retail) and current margin reset make multiples non-comparable.
B47: WHY MULTIPLES AREN'T CURRENCY-CONVERTED
C48: EV/Revenue, EV/EBITDA, EV/EBIT and P/E are unitless ratios - each comp's multiple is computed from its own numerator and denominator in its own reporting currency (EUR, CHF or HKD), so cross-currency comparison of the ratios is valid without FX conversion. Multiples are applied directly to LVMH's own EUR financials on the Implied Valuation tab, so all outputs are native EUR.
B50: TAB-BY-TAB WALKTHROUGH
B52: 1. Trading Comps | C52: Input (LTM financials per comp), Calculations (Market Cap, EV, multiples), Output (Mean/Median/Min/Max), Operating Metrics (growth, margins, ROE) and Forward (NTM) Multiples sections.
B54: 2. Implied Valuation | C54: Applies the comp set's median (and mean/min/max) multiples to LVMH's own LTM financials to derive implied EV, Equity Value and Share Price, plus the football field chart, sensitivity table and Key Takeaways.
B56: SOURCES (all via S&P Global Market Intelligence, as republished by stockanalysis.com / Simply Wall St)
...

Sheet Assumptions
A1: LVMH - COMPARABLE COMPANIES ANALYSIS
A3: KEY DATES & BASIS
A4: Valuation Date | B4: Aug 6, 2026
A5: Data Cut-Off Date | B5: Aug 6, 2026 (comp data collected Jul 30 - Aug 6, 2026; see Sources tab)
A6: Financial Basis | B6: LTM / TTM per company, native reporting currency (no FX conversion applied to multiples)
A8: CURRENT SHARE PRICES (as of Data Date, native currency)
A9: Company | B9: Ticker | C9: Currency | D9: Share Price | E9: Price Date
A10: LVMH | B10: MC | C10: EUR | D10: 468.55 | E10: Aug 5, 2026
A11: Hermes | B11: RMS | C11: EUR | D11: 2124 | E11: Aug 5, 2026
A12: Kering | B12: KER | C12: EUR | D12: 288.35 | E12: Jul 30, 2026
A13: Richemont | B13: CFR | C13: CHF | D13: 148.24 | E13: May 1, 2026
A14: Prada | B14: 1913 | C14: HKD | D14: 38.74 | E14: Aug 2026
A15: Moncler | B15: MONC | C15: EUR | D15: 47.35 | E15: Jul 31, 2026
A16: Brunello Cucinelli | B16: BC | C16: EUR | D16: 86 | E16: Aug 2026
A18: FISCAL YEAR END (by company)
A19: LVMH | B19: Dec 31
A20: Hermes | B20: Dec 31
A21: Kering | B21: Dec 31
A22: Richemont | B22: Mar 31
A23: Prada | B23: Dec 31 (HKD listing)
A24: Moncler | B24: Dec 31
A25: Brunello Cucinelli | B25: Dec 31
A27: MODELLING ASSUMPTIONS
A28: - Multiples (EV/Revenue, EV/EBITDA, EV/EBIT, P/E) are unitless ratios computed within each company's own currency - not cross-currency converted.
A29: - LVMH is shown for reference alongside the comp set but excluded from Mean/Median/Min/Max statistics.
A30: - Implied valuation applies comp set median (and mean/min/max) multiples to LVMH's own LTM financials.
A31: - Net debt, EPS and other inputs are hardcoded from source data (blue text); all other cells are formulas (black) or cross-sheet links (green).
A32: - Comp data spans a research window of ~Jul 2025-Aug 2026 across sources with differing update cadences (esp. Richemont FY to March, Prada HKD listing).

Sheet Sources
A1: LVMH - COMPARABLE COMPANIES ANALYSIS
A2: DATA SOURCES
A4: Company | B4: Primary Source | C4: Source Type | D4: Data Items Sourced | E4: As-Of Date / Period
A5: LVMH (EPA:MC) | B5: Company IR / Annual Report; S&P Global Mkt Intelligence via stockanalysis.com | C5: Company IR, Annual Report, Market Data Aggregator | D5: Share price, shares o/s, net debt, revenue, EBITDA, EBIT, net income, EPS, NTM estimates | E5: Aug 5, 2026 (FY2025 Annual Report)
A6: Hermes (EPA:RMS) | B6: S&P Global Mkt Intelligence via stockanalysis.com / Simply Wall St | C6: Market Data Aggregator | D6: Same LTM/NTM financial line items as above | E6: Aug 5-6, 2026
A7: Kering (EPA:KER) | B7: S&P Global Mkt Intelligence via stockanalysis.com / Simply Wall St | C7: Market Data Aggregator | D7: Same LTM/NTM financial line items as above | E7: Jul 30 - Aug 6, 2026
A8: Richemont (SWX:CFR) | B8: S&P Global Mkt Intelligence via stockanalysis.com / Simply Wall St | C8: Market Data Aggregator | D8: Same LTM/NTM financial line items as above | E8: May-Aug 2026 (FY to March)
A9: Prada (HKG:1913) | B9: S&P Global Mkt Intelligence via stockanalysis.com / Simply Wall St | C9: Market Data Aggregator | D9: Same LTM/NTM financial line items as above, quoted in HKD | E9: Jul-Oct 2025 / Aug 2026
A10: Moncler (BIT:MONC) | B10: S&P Global Mkt Intelligence via stockanalysis.com / Simply Wall St | C10: Market Data Aggregator | D10: Same LTM/NTM financial line items as above | E10: Jul-Aug 2026
A11: Brunello Cucinelli (BIT:BC) | B11: S&P Global Mkt Intelligence via stockanalysis.com / Simply Wall St | C11: Market Data Aggregator | D11: Same LTM/NTM financial line items as above | E11: Aug 2026
A13: OTHER REFERENCE SOURCES
A14: Company Annual Reports / 10-K / 20-F equivalents | B14: Segment detail, business description, Maison/brand portfolio (Model Guide tab)
A15: Investor Presentations | B15: Strategic commentary, segment margin bridges (qualitative context only, not hardcoded)
A16: Yahoo Finance | B16: Cross-check / secondary reference for share price and market data
A17: Macrotrends | B17: Historical trend cross-check for revenue/margin sanity-checking
A19: NOTE
A20: Comp data spans a research window of roughly Jul 2025-Aug 2026 across sources with differing update cadences; see Model Guide tab for full detail.

Sheet Trading Comps
A1: LVMH - COMPARABLE COMPANIES ANALYSIS
A3: INPUT - COMPARABLE COMPANY DATA (LTM / TTM, native reporting currency)
A5: Company | B5: Ticker | C5: Ccy | D5: Share Price | E5: Shares O/S (m) | F5: Net Debt (m) | G5: Revenue LTM (m) | H5: EBITDA LTM (m) | I5: EBIT LTM (m) | J5: Net Income LTM (m) | K5: EPS LTM | L5: Data Date | M5: Prior Yr Revenue (m) | N5: Shareholders' Equity (m) | O5: NTM Revenue (m) | P5: NTM EPS
A6: Hermes | B6: RMS | C6: EUR | D6: 2124 | E6: 104.85 | F6: -10030 | G6: 16130 | H6: 7230 | I6: 6750 | J6: 4520 | K6: 43 | L6: Aug 5, 2026 | M6: 15170 | N6: 17760 | O6: 17420 | P6: 46.44
A7: Kering | B7: KER | C7: EUR | D7: 288.35 | E7: 123.9 | F7: 14250 | G7: 14680 | H7: 2940 | I7: 1630 | J7: 72 | K7: 0.59 | L7: Jul 30, 2026 | M7: 16870 | N7: 28800 | O7: 15200 | P7: 5.48
A8: Richemont | B8: CFR | C8: CHF | D8: 148.24 | E8: 588.96 | F8: -1740 | G8: 20530 | H8: 5535 | I8: 4346 | J8: 3840 | K8: 6.52 | L8: May 1, 2026 | M8: 19779 | N8: 21180 | O8: 21760 | P8: 6.91
A9: Prada | B9: 1913 | C9: HKD | D9: 38.74 | E9: 2560 | F9: 32670 | G9: 52250 | H9: 18890 | I9: 14100 | J9: 7790 | K9: 3.04 | L9: Aug 2026 | M9: 49413 | N9: 41086 | O9: 56430 | P9: 2.92
A10: Moncler | B10: MONC | C10: EUR | D10: 47.35 | E10: 271.6 | F10: -348.9 | G10: 3200 | H10: 930 | I10: 586 | J10: 637.9 | K10: 2.35 | L10: Jul 31, 2026 | M10: 3130 | N10: 3785 | O10: 3328 | P10: 2.03
A11: Brunello Cucinelli | B11: BC | C11: EUR | D11: 86 | E11: 68 | F11: 890 | G11: 1473 | H11: 349 | I11: 221 | J11: 137.9 | K11: 2.03 | L11: Aug 2026 | M11: 1340 | N11: 473.6 | O11: 1620 | P11: 1.91
A13: LVMH (TARGET) | B13: MC | C13: EUR | D13: 468.55 | E13: 496.39 | F13: 24740 | G13: 80810 | H13: 23830 | I13: 17780 | J13: 10880 | K13: 21.92 | L13: Aug 5, 2026 | M13: 84680 | N13: 67000 | O13: 83640 | P13: 23.37
A16: CALCULATIONS - MARKET CAP, ENTERPRISE VALUE & TRADING MULTIPLES (LTM)
A18: Company | B18: Market Cap (m) | C18: Enterprise Value (m) | D18: EV / Revenue | E18: EV / EBITDA | F18: EV / EBIT | G18: P / E *
A19: =A6 -> Hermes | B19: =D6*E6 -> 222701.4 | C19: =B19+F6 -> 212671.4 | D19: =C19/G6 -> 13.184836 | E19: =C19/H6 -> 29.415131 | F19: =C19/I6 -> 31.506874 | G19: =D6/K6 -> 49.395349
A20: =A7 -> Kering | B20: =D7*E7 -> 35726.565 | C20: =B20+F7 -> 49976.565 | D20: =C20/G7 -> 3.4043982 | E20: =C20/H7 -> 16.998832 | F20: =C20/I7 -> 30.660469 | G20: =D7/K7 -> 488.72881
A21: =A8 -> Richemont | B21: =D8*E8 -> 87307.43 | C21: =B21+F8 -> 85567.43 | D21: =C21/G8 -> 4.1679216 | E21: =C21/H8 -> 15.459337 | F21: =C21/I8 -> 19.688778 | G21: =D8/K8 -> 22.736196
A22: =A9 -> Prada | B22: =D9*E9 -> 99174.4 | C22: =B22+F9 -> 131844.4 | D22: =C22/G9 -> 2.5233378 | E22: =C22/H9 -> 6.9795871 | F22: =C22/I9 -> 9.3506667 | G22: =D9/K9 -> 12.743421
A23: =A10 -> Moncler | B23: =D10*E10 -> 12860.26 | C23: =B23+F10 -> 12511.36 | D23: =C23/G10 -> 3.9098 | E23: =C23/H10 -> 13.453075 | F23: =C23/I10 -> 21.350444 | G23: =D10/K10 -> 20.148936
A24: =A11 -> Brunello Cucinelli | B24: =D11*E11 -> 5848 | C24: =B24+F11 -> 6738 | D24: =C24/G11 -> 4.5743381 | E24: =C24/H11 -> 19.30659 | F24: =C24/I11 -> 30.488688 | G24: =D11/K11 -> 42.364532
A26: LVMH (TARGET) | B26: =D13*E13 -> 232583.53 | C26: =B26+F13 -> 257323.53 | D26: =C26/G13 -> 3.1843031 | E26: =C26/H13 -> 10.798302 | F26: =C26/I13 -> 14.47264 | G26: =D13/K13 -> 21.375456
A29: OUTPUT - SUMMARY STATISTICS (6 comparable companies; LVMH excluded)
A31: Statistic | B31: EV / Revenue | C31: EV / EBITDA | D31: EV / EBIT | E31: P / E
A32: Mean | B32: =AVERAGE(D19:D24) -> 5.2941052 | C32: =AVERAGE(E19:E24) -> 16.935425 | D32: =AVERAGE(F19:F24) -> 23.840987 | E32: =AVERAGE(G19,G21:G24) -> 29.477687
A33: Median | B33: =MEDIAN(D19:D24) -> 4.0388608 | C33: =MEDIAN(E19:E24) -> 16.229084 | D33: =MEDIAN(F19:F24) -> 25.919566 | E33: =MEDIAN(G19,G21:G24) -> 22.736196
A34: Minimum | B34: =MIN(D19:D24) -> 2.5233378 | C34: =MIN(E19:E24) -> 6.9795871 | D34: =MIN(F19:F24) -> 9.3506667 | E34: =MIN(G19,G21:G24) -> 12.743421
A35: Maximum | B35: =MAX(D19:D24) -> 13.184836 | C35: =MAX(E19:E24) -> 29.415131 | D35: =MAX(F19:F24) -> 31.506874 | E35: =MAX(G19,G21:G24) -> 49.395349
A36: * Kering's P/E of ~489x is NM (near-breakeven LTM net income) and is excluded from the Mean/Median/Min/Max; retained in the input/calc rows above for transparency.
A38: OPERATING METRICS
A40: Company | B40: Revenue Growth % | C40: EBITDA Margin % | D40: EBIT Margin % | E40: Net Margin % | F40: ROE %
A41: =A6 -> Hermes | B41: =(G6-M6)/M6 -> 0.063282795 | C41: =H6/G6 -> 0.44823311 | D41: =I6/G6 -> 0.41847489 | E41: =J6/G6 -> 0.28022319 | F41: =J6/N6 -> 0.2545045
A42: =A7 -> Kering | B42: =(G7-M7)/M7 -> -0.12981624 | C42: =H7/G7 -> 0.20027248 | D42: =I7/G7 -> 0.11103542 | E42: =J7/G7 -> 0.0049046322 | F42: =J7/N7 -> 0.0025
A43: =A8 -> Richemont | B43: =(G8-M8)/M8 -> 0.037969564 | C43: =H8/G8 -> 0.26960546 | D43: =I8/G8 -> 0.21169021 | E43: =J8/G8 -> 0.18704335 | F43: =J8/N8 -> 0.18130312
A44: =A9 -> Prada | B44: =(G9-M9)/M9 -> 0.057414041 | C44: =H9/G9 -> 0.3615311 | D44: =I9/G9 -> 0.26985646 | E44: =J9/G9 -> 0.14909091 | F44: =J9/N9 -> 0.1896023
A45: =A10 -> Moncler | B45: =(G10-M10)/M10 -> 0.022364217 | C45: =H10/G10 -> 0.290625 | D45: =I10/G10 -> 0.183125 | E45: =J10/G10 -> 0.19934375 | F45: =J10/N10 -> 0.16853369
A46: =A11 -> Brunello Cucinelli | B46: =(G11-M11)/M11 -> 0.099253731 | C46: =H11/G11 -> 0.23693143 | D46: =I11/G11 -> 0.15003394 | E46: =J11/G11 -> 0.093618466 | F46: =J11/N11 -> 0.29117399
A48: LVMH (TARGET) | B48: =(G13-M13)/M13 -> -0.045701464 | C48: =H13/G13 -> 0.29488925 | D48: =I13/G13 -> 0.22002227 | E48: =J13/G13 -> 0.1346368 | F48: =J13/N13 -> 0.16238806
A50: Statistic | B50: Revenue Growth % | C50: EBITDA Margin % | D50: EBIT Margin % | E50: Net Margin % | F50: ROE %
A51: Mean | B51: =AVERAGE(B41:B46) -> 0.025078018 | C51: =AVERAGE(C41:C46) -> 0.30119976 | D51: =AVERAGE(D41:D46) -> 0.22403599 | E51: =AVERAGE(E41:E46) -> 0.15237072 | F51: =AVERAGE(F41:F46) -> 0.1812696
A52: Median | B52: =MEDIAN(B41:B46) -> 0.047691802 | C52: =MEDIAN(C41:C46) -> 0.28011523 | D52: =MEDIAN(D41:D46) -> 0.1974076 | E52: =MEDIAN(E41:E46) -> 0.16806713 | F52: =MEDIAN(F41:F46) -> 0.18545271
A53: Minimum | B53: =MIN(B41:B46) -> -0.12981624 | C53: =MIN(C41:C46) -> 0.20027248 | D53: =MIN(D41:D46) -> 0.11103542 | E53: =MIN(E41:E46) -> 0.0049046322 | F53: =MIN(F41:F46) -> 0.0025
A54: Maximum | B54: =MAX(B41:B46) -> 0.099253731 | C54: =MAX(C41:C46) -> 0.44823311 | D54: =MAX(D41:D46) -> 0.41847489 | E54: =MAX(E41:E46) -> 0.28022319 | F54: =MAX(F41:F46) -> 0.29117399
...

Sheet Implied Valuation
A1: LVMH - IMPLIED VALUATION FROM TRADING COMPS
A3: LVMH - LTM FINANCIALS (linked from Trading Comps)
A4: Share Price (EUR) | B4: ='Trading Comps'!D13 -> 468.55
A5: Shares Outstanding (m) | B5: ='Trading Comps'!E13 -> 496.39
A6: Net Debt (EURm) | B6: ='Trading Comps'!F13 -> 24740
A7: Revenue LTM (EURm) | B7: ='Trading Comps'!G13 -> 80810
A8: EBITDA LTM (EURm) | B8: ='Trading Comps'!H13 -> 23830
A9: EBIT LTM (EURm) | B9: ='Trading Comps'!I13 -> 17780
A10: Net Income LTM (EURm) | B10: ='Trading Comps'!J13 -> 10880
A11: EPS LTM (EUR) | B11: ='Trading Comps'!K13 -> 21.92
A13: IMPLIED VALUATION BY METHODOLOGY (median comp multiple applied to LVMH)
A15: Methodology | B15: Median Multiple | C15: LVMH Metric (EURm) | D15: Implied EV (EURm) | E15: Implied Equity Value (EURm) | F15: Implied Share Price (EUR)
A16: EV / Revenue | B16: ='Trading Comps'!B33 -> 4.0388608 | C16: =$B$7 -> 80810 | D16: =B16*C16 -> 326380.34 | E16: =D16-$B$6 -> 301640.34 | F16: =E16/$B$5 -> 607.66805
A17: EV / EBITDA | B17: ='Trading Comps'!C33 -> 16.229084 | C17: =$B$8 -> 23830 | D17: =B17*C17 -> 386739.08 | E17: =D17-$B$6 -> 361999.08 | F17: =E17/$B$5 -> 729.26344
A18: EV / EBIT | B18: ='Trading Comps'!D33 -> 25.919566 | C18: =$B$9 -> 17780 | D18: =B18*C18 -> 460849.88 | E18: =D18-$B$6 -> 436109.88 | F18: =E18/$B$5 -> 878.56298
A19: P / E | B19: ='Trading Comps'!E33 -> 22.736196 | C19: =$B$11 -> 21.92 | D19: =E19+$B$6 -> 272129.57 | E19: =F19*$B$5 -> 247389.57 | F19: =B19*C19 -> 498.37742
A20: Note: EV/Revenue and P/E ranges are wide - the comp set spans Kering (margin-impaired) to Hermes/Brunello Cucinelli (premium-rated). EV/EBITDA and EV/EBIT are the more defensible read for this comp set; treat EV/Revenue as a sanity check only.
A22: FOOTBALL FIELD - IMPLIED SHARE PRICE RANGE (EUR)
A24: Methodology | B24: Low (Min multiple) | C24: Median | D24: High (Max multiple) | E24: Bar Base (=Low) | F24: Bar Range (High-Low) | G24: Current Price (ref) | H24: Current Price | I24: P25 | J24: P75
A25: EV / Revenue | B25: =(('Trading Comps'!$B$34*$B$7)-$B$6)/$B$5 -> 360.9479 | C25: =(('Trading Comps'!$B$33*$B$7)-$B$6)/$B$5 -> 607.66805 | D25: =(('Trading Comps'!$B$35*$B$7)-$B$6)/$B$5 -> 2096.5905 | E25: =MIN(B25:D25) -> 360.9479 | F25: =MAX(B25:D25)-E25 -> 1735.6426 | G25: =$B$4 -> 468.55 | H25: =$B$30 -> 468.55 | I25: =$B$31 -> 580.34539 | J25: =$B$32 -> 766.58833
A26: EV / EBITDA | B26: =(('Trading Comps'!$C$34*$B$7)-$B$6)/$B$5 -> 1086.4047 | C26: =(('Trading Comps'!$C$33*$B$7)-$B$6)/$B$5 -> 2592.1801 | D26: =(('Trading Comps'!$C$35*$B$7)-$B$6)/$B$5 -> 4738.8077 | E26: =MIN(B26:D26) -> 1086.4047 | F26: =MAX(B26:D26)-E26 -> 3652.403 | G26: =$B$4 -> 468.55 | H26: =$B$30 -> 468.55 | I26: =$B$31 -> 580.34539 | J26: =$B$32 -> 766.58833
A27: EV / EBIT | B27: =(('Trading Comps'!$D$34*$B$7)-$B$6)/$B$5 -> 1472.4055 | C27: =(('Trading Comps'!$D$33*$B$7)-$B$6)/$B$5 -> 4169.7458 | D27: =(('Trading Comps'!$D$35*$B$7)-$B$6)/$B$5 -> 5079.3338 | E27: =MIN(B27:D27) -> 1472.4055 | F27: =MAX(B27:D27)-E27 -> 3606.9283 | G27: =$B$4 -> 468.55 | H27: =$B$30 -> 468.55 | I27: =$B$31 -> 580.34539 | J27: =$B$32 -> 766.58833
A28: P / E | B28: ='Trading Comps'!$E$34*$B$11 -> 279.33579 | C28: ='Trading Comps'!$E$33*$B$11 -> 498.37742 | D28: ='Trading Comps'!$E$35*$B$11 -> 1082.746 | E28: =MIN(B28:D28) -> 279.33579 | F28: =MAX(B28:D28)-E28 -> 803.41026 | G28: =$B$4 -> 468.55 | H28: =$B$30 -> 468.55 | I28: =$B$31 -> 580.34539 | J28: =$B$32 -> 766.58833
A30: Current Share Price (reference line) | B30: =$B$4 -> 468.55
A31: 25th Percentile (implied price) | B31: =PERCENTILE(F16:F19,0.25) -> 580.34539
A32: 75th Percentile (implied price) | B32: =PERCENTILE(F16:F19,0.75) -> 766.58833
A34: Statistic | B34: Implied EV (EURm) | C34: Implied Equity Value (EURm) | D34: Implied Share Price (EUR)
A35: Mean | B35: =AVERAGE('Trading Comps'!B32*$B$7,'Trading Comps'!C32*$B$8,'Trading Comps'!D32*$B$9,('Trading Comps'!E32*$B$11)+$B$6) -> 320166.68 | C35: =B35-$B$6 -> 295426.68 | D35: =C35/$B$5 -> 595.15035
A36: Median | B36: =AVERAGE('Trading Comps'!B33*$B$7,'Trading Comps'!C33*$B$8,'Trading Comps'!D33*$B$9,('Trading Comps'!E33*$B$11)+$B$6) -> 299801.92 | C36: =B36-$B$6 -> 275061.92 | D36: =C36/$B$5 -> 554.12462
A37: Minimum | B37: =AVERAGE('Trading Comps'!B34*$B$7,'Trading Comps'!C34*$B$8,'Trading Comps'!D34*$B$9,('Trading Comps'!E34*$B$11)+$B$6) -> 140377.17 | C37: =B37-$B$6 -> 115637.17 | D37: =C37/$B$5 -> 232.95628
A38: Maximum | B38: =AVERAGE('Trading Comps'!B35*$B$7,'Trading Comps'!C35*$B$8,'Trading Comps'!D35*$B$9,('Trading Comps'!E35*$B$11)+$B$6) -> 588111.03 | C38: =B38-$B$6 -> 563371.03 | D38: =C38/$B$5 -> 1134.9363
A40: Current Share Price (reference) | D40: =$B$4 -> 468.55
A62: SENSITIVITY ANALYSIS - IMPLIED SHARE PRICE vs. MULTIPLE FLEX (EUR)
A64: Multiple Flex | B64: EV/Revenue | C64: EV/EBITDA | D64: EV/EBIT | E64: P/E
A65: -0.2 | B65: =(('Trading Comps'!$B$33*(1+$A65)*$B$7)-$B$6)/$B$5 -> 476.16647 | C65: =(('Trading Comps'!$C$33*(1+$A65)*$B$8)-$B$6)/$B$5 -> 573.44278 | D65: =(('Trading Comps'!$D$33*(1+$A65)*$B$9)-$B$6)/$B$5 -> 692.88242 | E65: =('Trading Comps'!$E$33*(1+$A65))*$B$11 -> 398.70194
A66: -0.1 | B66: =(('Trading Comps'!$B$33*(1+$A66)*$B$7)-$B$6)/$B$5 -> 541.91726 | C66: =(('Trading Comps'!$C$33*(1+$A66)*$B$8)-$B$6)/$B$5 -> 651.35311 | D66: =(('Trading Comps'!$D$33*(1+$A66)*$B$9)-$B$6)/$B$5 -> 785.7227 | E66: =('Trading Comps'!$E$33*(1+$A66))*$B$11 -> 448.53968
A67: 0 | B67: =(('Trading Comps'!$B$33*(1+$A67)*$B$7)-$B$6)/$B$5 -> 607.66805 | C67: =(('Trading Comps'!$C$33*(1+$A67)*$B$8)-$B$6)/$B$5 -> 729.26344 | D67: =(('Trading Comps'!$D$33*(1+$A67)*$B$9)-$B$6)/$B$5 -> 878.56298 | E67: =('Trading Comps'!$E$33*(1+$A67))*$B$11 -> 498.37742
A68: 0.1 | B68: =(('Trading Comps'!$B$33*(1+$A68)*$B$7)-$B$6)/$B$5 -> 673.41883 | C68: =(('Trading Comps'!$C$33*(1+$A68)*$B$8)-$B$6)/$B$5 -> 807.17377 | D68: =(('Trading Comps'!$D$33*(1+$A68)*$B$9)-$B$6)/$B$5 -> 971.40326 | E68: =('Trading Comps'!$E$33*(1+$A68))*$B$11 -> 548.21517
A69: 0.2 | B69: =(('Trading Comps'!$B$33*(1+$A69)*$B$7)-$B$6)/$B$5 -> 739.16962 | C69: =(('Trading Comps'!$C$33*(1+$A69)*$B$8)-$B$6)/$B$5 -> 885.0841 | D69: =(('Trading Comps'!$D$33*(1+$A69)*$B$9)-$B$6)/$B$5 -> 1064.2435 | E69: =('Trading Comps'!$E$33*(1+$A69))*$B$11 -> 598.05291
A71: Flex applied to each methodology's median comp multiple (Trading Comps row 33); 0% = base case shown in the Implied Valuation Summary above.
...

Sheet Luxury Industry Dashboard
A1: LUXURY INDUSTRY DASHBOARD
A3: BRAND PORTFOLIO
A5: Company | B5: # Major Maisons | C5: Key Brands
A6: LVMH | B6: 75 | C6: Louis Vuitton, Dior, Fendi, Tiffany & Co., Bulgari, Moet & Chandon, Hennessy, Sephora
A7: Hermes | B7: 1 | C7: Hermes (single-Maison house)
A8: Kering | B8: 7 | C8: Gucci, Saint Laurent, Bottega Veneta, Balenciaga, Alexander McQueen
A9: Richemont | B9: 20 | C9: Cartier, Van Cleef & Arpels, IWC, Jaeger-LeCoultre, Montblanc, Chloe
A10: Prada | B10: 4 | C10: Prada, Miu Miu, Versace, Church's
A11: Moncler | B11: 2 | C11: Moncler, Stone Island
A12: Brunello Cucinelli | B12: 1 | C12: Brunello Cucinelli (single-brand house)
A15: GEOGRAPHIC REVENUE MIX (approximate, illustrative - see note)
A17: Company | B17: Europe % | C17: Americas % | D17: Asia-Pacific % | E17: Other %
A18: LVMH | B18: 0.35 | C18: 0.25 | D18: 0.34 | E18: 0.06
A19: Hermes | B19: 0.25 | C19: 0.18 | D19: 0.5 | E19: 0.07
A20: Kering | B20: 0.22 | C20: 0.22 | D20: 0.48 | E20: 0.08
A21: Richemont | B21: 0.23 | C21: 0.19 | D21: 0.45 | E21: 0.13
A22: Prada | B22: 0.2 | C22: 0.15 | D22: 0.58 | E22: 0.07
A23: Moncler | B23: 0.35 | C23: 0.15 | D23: 0.45 | E23: 0.05
A24: Brunello Cucinelli | B24: 0.35 | C24: 0.35 | D24: 0.25 | E24: 0.05
A26: Note: illustrative regional splits based on general company disclosure patterns (not pulled line-by-line from each 10-K/annual report); verify against each company's segment reporting before use.
A28: REVENUE GROWTH, OPERATING MARGIN & MARKET CAPITALIZATION (linked from Trading Comps)
A30: Company | B30: Revenue Growth % | C30: Operating Margin % | D30: Market Cap (native ccy, m)
A31: LVMH | B31: ='Trading Comps'!B48 -> -0.045701464 | C31: ='Trading Comps'!D48 -> 0.22002227 | D31: ='Trading Comps'!B26 -> 232583.53
A32: Hermes | B32: ='Trading Comps'!B41 -> 0.063282795 | C32: ='Trading Comps'!D41 -> 0.41847489 | D32: ='Trading Comps'!B19 -> 222701.4
A33: Kering | B33: ='Trading Comps'!B42 -> -0.12981624 | C33: ='Trading Comps'!D42 -> 0.11103542 | D33: ='Trading Comps'!B20 -> 35726.565
A34: Richemont | B34: ='Trading Comps'!B43 -> 0.037969564 | C34: ='Trading Comps'!D43 -> 0.21169021 | D34: ='Trading Comps'!B21 -> 87307.43
A35: Prada | B35: ='Trading Comps'!B44 -> 0.057414041 | C35: ='Trading Comps'!D44 -> 0.26985646 | D35: ='Trading Comps'!B22 -> 99174.4
A36: Moncler | B36: ='Trading Comps'!B45 -> 0.022364217 | C36: ='Trading Comps'!D45 -> 0.183125 | D36: ='Trading Comps'!B23 -> 12860.26
A37: Brunello Cucinelli | B37: ='Trading Comps'!B46 -> 0.099253731 | C37: ='Trading Comps'!D46 -> 0.15003394 | D37: ='Trading Comps'!B24 -> 5848
A40: Note: Market Cap shown in each company's native reporting currency (EUR/CHF/HKD) - not FX-adjusted; see Model Guide.
A42: KEY DIFFERENCES: LVMH vs. PEER GROUP
A43: - Scale & diversification: ~75 Maisons across 5 segments vs. peers' 1-20 brands - LVMH's market cap (~EUR233bn) is ~2.6x Hermes and ~5x the next-largest conglomerate peer.
A44: - Margin profile: LVMH's ~29% EBITDA margin trails Hermes (~45%, single-Maison pricing power) but leads Kering (~20%, mid-turnaround) and sits mid-pack overall.
A45: - Growth: LVMH LTM revenue growth (-4.6%) lags the peer set - Brunello Cucinelli (+9.9%) and Hermes (+6.3%) outgrow, while Kering (-13.0%) underperforms.
A46: - Takeaway: LVMH trades as a diversified, lower-volatility mega-cap - scale over best-in-class margins/growth, consistent with its discount to peer-median multiples.
